Workbook

Sheet speciesGuide
A1: dataCode | B1: colName | C1: NameChanged | D1: SpeciesName | E1: LevelID | F1: CommonName_ENG | G1: CommonName_IND | H1: FishBase_TrophicScore | I1: FBTS_SE | J1: No_InGenus
A2: UNIDGUPPY | B2: MAXN_UNIDGUPPY | D2: Unidentified Fish
A3: GUPPYBOTH | B3: MAXN_GUPPYBOTH | D3: Parioglossus | E3: Genus | F3: Dartfish | H3: =AVERAGE(GenusTrophics!A2:A9) -> 3.1375 | I3: =_xlfn.STDEV.P(GenusTrophics!A2:A9) -> 0.069597055 | J3: =COUNT(GenusTrophics!A2:A9) -> 8
A4: GUPPYA | B4: MAXN_GUPPYA | C4: UNID_JUVENILE | D4: Unidentified Juvenile
A5: GUPPYB | B5: MAXN_GUPPYB | C5: SHRIMP | D5: Unidentified Shrimp
A6: BLOWFISH | B6: MAXN_BLOWFISH | D6: Aronthron | E6: Genus | F6: Puffer Fish | G6: Ikan Buntal | H6: =AVERAGE(GenusTrophics!B2:B10) -> 3.4111111 | I6: =_xlfn.STDEV.P(GenusTrophics!B2:B10) -> 0.2806518 | J6: =COUNT(GenusTrophics!B2:B10) -> 9
A7: FISHD | B7: MAXN_FISHD | D7: Toxotes jaculatrix | E7: Species | F7: Banded Archerfish | G7: Ikan Sumpit | H7: 2.6 | I7: 0.27
A8: FISHE | B8: MAXN_FISHE | D8: Lutjanus ehrenbergii | E8: Species | F8: Blackspot Snapper | G8: Kakap Garis | H8: 3.6 | I8: 0.53
A9: FISHF | B9: MAXN_FISHF | D9: Fibramia lateralis | E9: Species | F9: Humpback Cardinal | H9: 4 | I9: 0.6
A10: FISHG | B10: MAXN_FISHG | C10: FISHM | D10: Lutjanus argentimaculatus | E10: Species | F10: Mangrove Red Snapper | G10: Ikan Lencam | H10: 3.6 | I10: 0.5
A11: FISHH | B11: MAXN_FISHH | D11: Mugilidae | E11: Family | F11: Mullet | G11: Ikan Belanak | H11: =AVERAGE(GenusTrophics!C2:C21) -> 2.4 | I11: =_xlfn.STDEV.P(GenusTrophics!C2:C21) -> 0.20976177 | J11: =COUNT(GenusTrophics!C2:C21) -> 20
A12: FISHJ | B12: MAXN_FISHJ | D12: Scatophagus argus | E12: Species | F12: Spotted Scat | G12: Ikan Kiper | H12: 3 | I12: 0.35
A13: PIPEFISH | B13: MAXN_PIPEFISH | D13: Hyporhampus | E13: Genus | F13: Halfbeak | G13: Ikan julung-julung | H13: =AVERAGE(GenusTrophics!D2:D8) -> 3.1428571 | I13: =_xlfn.STDEV.P(GenusTrophics!D2:D8) -> 0.22587698 | J13: =COUNT(GenusTrophics!D2:D8) -> 7
A14: MUDCRAB | B14: MAXN_MUDCRAB
A15: SWIMMERCRAB | B15: MAXN_SWIMMERCRAB | D15: Portunidae | E15: Genus | F15: Swimmer Crab | H15: NA | I15: NA | J15: NA
A16: ULAR | B16: MAXN_ULAR | D16: Acrochordus granulatus | E16: Species | F16: Marine File Snake | H16: NA | I16: NA | J16: NA
A17: GUPPYC | B17: MAXN_GUPPYC | C17: FISHF | D17: Fibramia lateralis | E17: Species | F17: Humpback Cardinal | H17: 4 | I17: 0.6
A18: FISHK | B18: MAXN_FISHK | D18: Gerres oyena | E18: Species | F18: Blacktip Silverbiddy | G18: Ikan Kapas-kapas | H18: 2.7 | I18: 0.24
A19: FISHL | B19: MAXN_FISHL | C19: FISHK | D19: Gerres oyena | E19: Species | F19: Blacktip Silverbiddy | G19: Ikan Kapas-kapas | H19: 2.7 | I19: 0.24
A20: FISHM | B20: MAXN_FISHM | D20: Lutjanus argentimaculatus | E20: Species | F20: Mangrove Red Snapper | G20: Ikan Lencam | H20: 3.6 | I20: 0.5
A21: FISHN | B21: MAXN_FISHN | D21: Sphaeramia orbicularis | E21: Species | F21: Orbicular Cardinalfish | H21: 3.6 | I21: 0.51
A22: FISHO | B22: MAXN_FISHO | D22: Siganus | E22: Genus | F22: Gold Spotted Rabbitfish | G22: Ikan Baronang | H22: =AVERAGE(GenusTrophics!E2:E19) -> 2.3555556 | I22: =_xlfn.STDEV.P(GenusTrophics!E2:E19) -> 0.39891829 | J22: =COUNT(GenusTrophics!E2:E19) -> 18
A23: CHEETAGIRLZ | B23: MAXN_CHEETAGIRLZ | C23: FISHO | D23: Siganus | E23: Genus | F23: Gold Spotted Rabbitfish | G23: Ikan Baronang | H23: =AVERAGE(GenusTrophics!E2:E19) -> 2.3555556 | I23: =_xlfn.STDEV.P(GenusTrophics!E2:E19) -> 0.39891829 | J23: =COUNT(GenusTrophics!E2:E19) -> 18
A24: KERONGKERONG | B24: MAXN_KERONGKERONG | D24: Terapon jarbua | E24: Species | F24: Crescent Grunter | G24: Kerong Kerong | H24: 3.9 | I24: 0.5
A25: YL | B25: MAXN_YL | D25: Chaetodon | E25: Genus | F25: Butterfly Fish | G25: Ikan Kepe-kepe | H25: =AVERAGE(GenusTrophics!F2:F47) -> 3.2217391 | I25: =_xlfn.STDEV.P(GenusTrophics!F2:F47) -> 0.41384362 | J25: =COUNT(GenusTrophics!F2:F47) -> 46
A26: BFLY1 | B26: MAXN_BFLY1 | D26: Monodactylus argenteus | E26: Species | F26: Moonyfishes or fingerfishes | G26: Ikan Bebulan | H26: 3.1 | I26: 0.26
A27: VERTFISH | B27: MAXN_VERTFISH | C27: BIGBOI | D27: Sphyraena barracuda | E27: Species | F27: Great Barracuda | G27: Barakuda | H27: 4.5 | I27: 0.6
A28: SANDFISH | B28: MAXN_SANDFISH | D28: Omobranchus | E28: Genus | F28: Blenny | G28: Jabingan | H28: =AVERAGE(GenusTrophics!G2:G8) -> 2.7714286 | I28: =_xlfn.STDEV.P(GenusTrophics!G2:G8) -> 0.30572764 | J28: =COUNT(GenusTrophics!G2:G8) -> 7
A29: SHRIMP | B29: MAXN_SHRIMP | D29: Unidentified Shrimp
A30: YELLOWGUPPY | B30: MAXN_YELLOWGUPPY | C30: FISHA | D30: Ostorhinchus ocellicaudus OR ostorhinchus franssedai | E30: Species | F30: Tailete or Frans' cardinalfish | H30: 3.5 | I30: 0.4
A31: YELLOWSTRIPE | B31: MAXN_YELLOWSTRIPE | D31: Monodactylus argenteus | E31: Species | F31: Diamondfish | H31: 3.1 | I31: 0.26
A32: GARONGGONG | B32: MAXN_GARONGGONG | D32: Epinephelus coioides | E32: Species | F32: Orangespotted Grouper | G32: kerapu lumpur | H32: 4 | I32: 0
A33: FISHP | B33: MAXN_FISHP | C33: FISHQ | D33: Caranx | E33: Genus | F33: Trevally | G33: Ikan Kuwe | H33: =AVERAGE(GenusTrophics!H2:H9) -> 4.2 | I33: =_xlfn.STDEV.P(GenusTrophics!H2:H9) -> 0.25495098 | J33: =COUNT(GenusTrophics!H2:H9) -> 8
A34: LILFREAK | B34: MAXN_LILFREAK | C34: SANDFISH | D34: Omobranchus | E34: Genus | F34: Blenny | G34: Jabingan | H34: =AVERAGE(GenusTrophics!G2:G8) -> 2.7714286 | I34: =_xlfn.STDEV.P(GenusTrophics!G2:G8) -> 0.30572764 | J34: =COUNT(GenusTrophics!G2:G8) -> 7
A35: FISHA | B35: MAXN_FISHA | D35: Ostorhinchus ocellicaudus | E35: Species | F35: Tailspot cardinalfish | H35: 3.4 | I35: 0.4
A36: FISHQ | B36: MAXN_FISHQ | D36: Caranx | E36: Genus | F36: Trevally | G36: Ikan Kuwe | H36: =AVERAGE(GenusTrophics!H2:H9) -> 4.2 | I36: =_xlfn.STDEV.P(GenusTrophics!H2:H9) -> 0.25495098 | J36: =COUNT(GenusTrophics!H2:H9) -> 8
A37: FISHR | B37: MAXN_FISHR | C37: FISHF | D37: Fibramia lateralis | E37: Species | F37: Humpback Cardinal | H37: 4 | I37: 0.6
A38: FISHS | B38: MAXN_FISHS | C38: FISHQ | D38: Caranx | E38: Genus | F38: Trevally | G38: Ikan Kuwe | H38: =AVERAGE(GenusTrophics!H2:H9) -> 4.2 | I38: =_xlfn.STDEV.P(GenusTrophics!H2:H9) -> 0.25495098 | J38: =COUNT(GenusTrophics!H2:H9) -> 8
A39: EYELINER | B39: MAXN_EYELINER | C39: FISHE | D39: Lutjanus ehrenbergii | E39: Species | F39: Blackspot Snapper | G39: Kakap Garis | H39: 3.6 | I39: 0.53
A40: BIGBOI | B40: MAXN_BIGBOI | D40: Sphyraena barracuda | E40: Species | F40: Great Barracuda | G40: Barakuda | H40: 4.5 | I40: 0.83
...

Sheet GenusTrophics
A1: Parioglossus | B1: Aronthron | C1: Mugilidae | D1: Hyporhampus | E1: Siganus | F1: Chaetodon | G1: Omobranchus | H1: Caranx
A2: 3.1 | B2: 3.5 | C2: 2.4 | D2: 3.5 | E2: 2 | F2: 3.5 | G2: 2.7 | H2: 3.8
A3: 3.2 | B3: 3.2 | C3: 2.5 | D3: 3 | E3: 3.2 | F3: 3.3 | G3: 3.5 | H3: 4
A4: 3.1 | B4: 3.3 | C4: 2.5 | D4: 3.5 | E4: 2 | F4: 2.7 | G4: 2.6 | H4: 4.2
A5: 3 | B5: 3.8 | C5: 2.2 | D5: 3 | E5: 2 | F5: 3.3 | G5: 2.7 | H5: 4.5
A6: 3.1 | B6: 2.8 | C6: 2.2 | D6: 3 | E6: 2 | F6: 3.7 | G6: 2.7 | H6: 4.5
A7: 3.2 | B7: 3.6 | C7: 2.3 | D7: 3 | E7: 2.7 | F7: 3.3 | G7: 2.5 | H7: 4
A8: 3.2 | B8: 3.4 | C8: 2.3 | D8: 3 | E8: 2.4 | F8: 3.1 | G8: 2.7 | H8: 4.5
A9: 3.2 | B9: 3.4 | C9: 2.3 | E9: 2 | F9: 3.5 | H9: 4.1
B10: 3.7 | C10: 2.3 | E10: 2.7 | F10: 3.5
C11: 2.5 | E11: 3 | F11: 3.8
C12: 2.4 | E12: 2 | F12: 2.6
C13: 2.2 | E13: 2 | F13: 3
C14: 2.5 | E14: 2 | F14: 3.5
C15: 2.3 | E15: 2.7 | F15: 3.6
C16: 2.8 | E16: 2.3 | F16: 2.8
C17: 2.3 | E17: 2 | F17: 3.1
C18: 2 | E18: 2.7 | F18: 3.4
C19: 2.7 | E19: 2.7 | F19: 2.9
C20: 2.4 | F20: 3.4
C21: 2.9 | F21: 3.7
F22: 3.3
F23: 2.8
F24: 4.4
F25: 3
F26: 3.3
F27: 3.3
F28: 2.6
F29: 3.3
F30: 3.5
F31: 2.9
F32: 3.3
F33: 3.4
... F47: 2.8
